#VRML_SIM R2021a utf8
WorldInfo {
  basicTimeStep 16
  coordinateSystem "NUE"
}
Viewpoint {
  orientation 0.12971499412007514 -0.9825295229989349 -0.13345320054578802 4.666369177918673
  position 1.3634101065105184 0.3805755202689537 0.14296286694455526
}
TexturedBackground {
}
TexturedBackgroundLight {
}
Floor {
}
Robot {
  translation 0 0.1 0
  rotation 1 0 0 1.5708
  children [
    DEF BODY Group {
      children [
        Transform {
          translation 0 -0.1 0.01
          rotation 1 0 0 -0.1308996938995747
          children [
            Shape {
              appearance DEF BODY_APPEARANCE PBRAppearance {
                baseColor 0.666667 0.333333 0
                roughness 1
                metalness 0
              }
              geometry Capsule {
                height 0.05
                radius 0.05
              }
            }
          ]
        }
        Transform {
          translation 0 0.08 0.01
          children [
            Shape {
              appearance USE BODY_APPEARANCE
              geometry Sphere {
                radius 0.04
                subdivision 2
              }
            }
          ]
        }
        Shape {
          appearance USE BODY_APPEARANCE
          geometry Sphere {
            radius 0.05
            subdivision 2
          }
        }
      ]
    }
    DEF LEG1 HingeJoint {
      jointParameters HingeJointParameters {
        anchor 0.03 0.03 0.03
      }
      device [
        RotationalMotor {
          name "l1"
        }
      ]
      endPoint Solid {
        translation 0.03 0.03 0.03
        rotation 1 0 0 3.14159
        children [
          DEF G_LEG Group {
            children [
              Shape {
                appearance USE BODY_APPEARANCE
                geometry Box {
                  size 0.01 0.01 0.01
                }
              }
              Transform {
                translation 0.0186603 2.6078e-08 0.025
                rotation -0.44721292362185294 -0.44721392362168216 0.774596867708936 1.82348
                children [
                  Shape {
                    appearance USE BODY_APPEARANCE
                    geometry Capsule {
                      height 0.05
                      radius 0.005
                    }
                  }
                ]
              }
            ]
          }
        ]
        boundingObject USE G_LEG
        physics Physics {
        }
      }
    }
    DEF LEG2 HingeJoint {
      jointParameters HingeJointParameters {
        anchor -0.03 0.03 0.03
      }
      device [
        RotationalMotor {
          name "l2"
        }
      ]
      endPoint Solid {
        translation -0.03 0.03 0.03
        rotation 0 0 1 3.14159
        children [
          USE G_LEG
        ]
        boundingObject USE G_LEG
        physics Physics {
        }
      }
    }
    DEF LEG3 HingeJoint {
      jointParameters HingeJointParameters {
        anchor 0.03 -0.03 0.03
      }
      device [
        RotationalMotor {
          name "l3"
        }
      ]
      endPoint Solid {
        translation 0.03 -0.03 0.03
        rotation 1 0 0 0
        children [
          USE G_LEG
        ]
        name "solid(1)"
        boundingObject USE G_LEG
        physics Physics {
        }
      }
    }
    DEF LEG4 HingeJoint {
      jointParameters HingeJointParameters {
        anchor -0.03 -0.03 0.03
      }
      device [
        RotationalMotor {
          name "l4"
        }
      ]
      endPoint Solid {
        translation -0.03 -0.03 0.03
        rotation 1.3267899999988322e-06 0.9999999999991198 4.794899999995779e-09 3.14159
        children [
          USE G_LEG
        ]
        name "solid(2)"
        boundingObject USE G_LEG
        physics Physics {
        }
      }
    }
  ]
  boundingObject USE BODY
  physics Physics {
  }
  controller "leg_movement"
}
